Workbook

Sheet 说明
A1: 云屿小筑 · 配置表与开发进度
A2: 数据源：03_数值与配置表.md、06_开发计划.md。本工作簿是它们的可计算版本（带公式校验）。
A4: 工作表索引
A5: 工作表 | B5: 类型 | C5: 内容
A6: 校验 | B6: 计算 | C6: 配置一致性与计划校验（引用完整性、概率、订单示例、计划容量）
A7: 开发进度 | B7: 管理 | C7: 里程碑日期与工时、P0 功能完成度、作品集交付物看板
A8: Global | B8: 配置 | C8: 全局常量
A9: Item | B9: 配置 | C9: 物品总表（作物 / 种子 / 加工品 / 采集物 / 工具 / 货币）
A10: Crop | B10: 配置 | C10: 作物（含每小时净收益计算列）
A11: GatherNode | B11: 配置 | C11: 采集点（含单次期望价值）
A12: Tool | B12: 配置 | C12: 工具升级
A13: Facility | B13: 配置 | C13: 加工设施
A14: FacilityLevel | B14: 配置 | C14: 设施升级（槽位 / 速度 / 成本）
A15: Recipe | B15: 配置 | C15: 配方（含增值倍率计算列）
A16: Level | B16: 配置 | C16: 等级经验（公式 + 可调参数）
... A26: Activity | B26: 配置 | C26: 活动
A28: 约定
A29: 颜色 | B29: 蓝色字 = 写死的数值输入；黑色字 = 公式；绿色字 = 引用其他工作表的公式；黄色底 = 可编辑的参数 / 状态；灰色底 = 计算列。
A30: 表头 | B30: 配置表前 3 行为：字段名 / 类型 / 中文注释，数据从第 4 行开始，可直接交给导表工具。
A31: 计算列 | B31: 字段名以 # 开头的列是校验用计算列，导表时应忽略。
A32: 列表字段 | B32: Recipe / Tool / FacilityLevel 的材料拆成 in1 / in2 / mat1~3 等列，便于公式；与 03 文档第 13 节的“;”列表写法等价。
A33: 时间与金额 | B33: 时间单位为秒，金额单位为金币（G）；活动开始 / 结束时间由服务端配置，表中留空。
A35: 假设与已知偏差
A36: 假设 1 | B36: Item.unlockLevel：肥料（1）、斧头（1）、镐（3）、采集篮（1）、货币（1）在 03 文档中未明确，此处为假设值。
A37: 假设 2 | B37: Item.sellPrice = 0 表示不可出售（种子、工具、货币、肥料）；buyPrice = 0 表示不在商店出售。
A38: 假设 3 | B38: Tool 表按“每种工具 × 3 个等级”展开 9 行（03 文档仅给出通用规则，三种工具规则相同）。
A39: 偏差 1 | B39: ="加工品增值倍率实际范围 "&TEXT(校验!C26,"0.00")&"x ~ "&TEXT(校验!C27,"0.00")&"x（03 文档原写 1.1~1.9，已更正）" -> 加工品增值倍率实际范围 1.33x ~ 2.25x（03 文档原写 1.1~1.9，已更正）
A40: 偏差 2 | B40: ="开发计划：核心线估时相对周容量的余量为 "&TEXT(校验!C23,"0.0")&" h（负数表示 M0 / M1 估时超出周容量，需动用缓冲或将 PoC #8 延后）" -> 开发计划：核心线估时相对周容量的余量为 -7.0 h（负数表示 M0 / M1 估时超出周容量，需动用缓冲或将 PoC #8 延后）

Sheet 校验
A1: 配置一致性与计划校验
A2: 全部为公式；状态列 OK = 与文档（03 / 06）一致。蓝色“期望值”来自文档，改配置后可立即看到偏差。
A4: 检查项 | B4: 期望值 | C4: 实际值 | D4: 状态 | E4: 说明 / 来源
A5: 稀有度基础概率之和 | B5: 1 | C5: =SUM(GachaRule!$B$4:$B$7) -> 1 | D5: =IF(ABS(C5-B5)<=0.000000001,"OK","检查") -> OK | E5: 03 §11.1：SSR+SR+R+N = 100%
A6: 常驻外观数量 N | B6: 12 | C6: =COUNTIFS(AvatarItem!$G$4:$G$39,"常驻",AvatarItem!$D$4:$D$39,"N") -> 12 | D6: =IF(ABS(C6-B6)<=0,"OK","检查") -> OK | E6: 03 §10.1 统计
A7: 常驻外观数量 R | B7: 10 | C7: =COUNTIFS(AvatarItem!$G$4:$G$39,"常驻",AvatarItem!$D$4:$D$39,"R") -> 10 | D7: =IF(ABS(C7-B7)<=0,"OK","检查") -> OK | E7: 03 §10.1 统计
A8: 常驻外观数量 SR | B8: 5 | C8: =COUNTIFS(AvatarItem!$G$4:$G$39,"常驻",AvatarItem!$D$4:$D$39,"SR") -> 5 | D8: =IF(ABS(C8-B8)<=0,"OK","检查") -> OK | E8: 03 §10.1 统计
A9: 常驻外观数量 SSR | B9: 3 | C9: =COUNTIFS(AvatarItem!$G$4:$G$39,"常驻",AvatarItem!$D$4:$D$39,"SSR") -> 3 | D9: =IF(ABS(C9-B9)<=0,"OK","检查") -> OK | E9: 03 §10.1 统计
A10: 限时池(P02)外观数量 | B10: 6 | C10: =COUNTIF(AvatarItem!$G$4:$G$39,"P02") -> 6 | D10: =IF(ABS(C10-B10)<=0,"OK","检查") -> OK | E10: 03 §10.2
A11: 配方产物 ID 无效数 | B11: 0 | C11: =SUMPRODUCT(--(COUNTIF(Item!$A$4:$A$44,Recipe!$I$4:$I$14)=0)) -> 0 | D11: =IF(ABS(C11-B11)<=0,"OK","检查") -> OK | E11: 引用完整性：产物必须存在于 Item
A12: 配方材料 ID 无效数 | B12: 0 | C12: =SUMPRODUCT(--(COUNTIF(Item!$A$4:$A$44,Recipe!$E$4:$E$14)=0))+SUMPRODUCT((Recipe!$G$4:$G$14<>"")*(COUNTIF(Item!$A$4:$A$44,Recipe!$G$4:$G$14)=0)) -> 0 | D12: =IF(ABS(C12-B12)<=0,"OK","检查") -> OK | E12: 引用完整性
A13: 作物种子 / 产出 ID 无效数 | B13: 0 | C13: =SUMPRODUCT(--(COUNTIF(Item!$A$4:$A$44,Crop!$C$4:$C$10)=0))+SUMPRODUCT(--(COUNTIF(Item!$A$4:$A$44,Crop!$D$4:$D$10)=0)) -> 0 | D13: =IF(ABS(C13-B13)<=0,"OK","检查") -> OK | E13: 引用完整性
A14: 卡池物品 ID 无效数 | B14: 0 | C14: =SUMPRODUCT(--(COUNTIF(AvatarItem!$A$4:$A$39,GachaPoolItem!$C$4:$C$57)=0)) -> 0 | D14: =IF(ABS(C14-B14)<=0,"OK","检查") -> OK | E14: 引用完整性：卡池物品必须存在于 AvatarItem
A15: 升至 Lv20 累计经验 | B15: 8759 | C15: =Level!$C$22 -> 8759 | D15: =IF(ABS(C15-B15)<=0,"OK","检查") -> OK | E15: 03 §7.1
A16: 平均出 SSR 所需抽数 | B16: 36.3 | C16: =GachaSim!$E$4 -> 36.3041 | D16: =IF(ABS(C16-B16)<=0.05,"OK","检查") -> OK | E16: 03 §11.4（脚本模拟 36.3）
A17: 50 抽内出 SSR 概率 | B17: 0.976 | C17: =GachaSim!$E$6 -> 0.9756941 | D17: =IF(ABS(C17-B17)<=0.001,"OK","检查") -> OK | E17: 03 §11.4（97.6%）；需 GachaSim!B10 = 50
A18: 综合 SSR 出率 | B18: 0.0275 | C18: =GachaSim!$E$7 -> 0.027545098 | D18: =IF(ABS(C18-B18)<=0.0005,"OK","检查") -> OK | E18: 03 §11.4（约 2.75%）
A19: 平均出 UP 所需抽数 | B19: 54.5 | C19: =GachaSim!$E$8 -> 54.45615 | D19: =IF(ABS(C19-B19)<=0.1,"OK","检查") -> OK | E19: 03 §11.4（约 54.5）
A20: 订单示例：草莓蛋糕×2+南瓜派+玉米饼 金币 | B20: 1344 | C20: =OrderCalc!$K$8 -> 1344 | D20: =IF(ABS(C20-B20)<=0,"OK","检查") -> OK | E20: 03 §8.2 示例
A21: 订单示例：面包×2 经验 | B21: 45 | C21: =OrderCalc!$L$6 -> 45 | D21: =IF(ABS(C21-B21)<=0,"OK","检查") -> OK | E21: 03 §8.2 示例
A22: 核心线总周数 | B22: 32 | C22: =开发进度!$D$18 -> 32 | D22: =IF(ABS(C22-B22)<=0,"OK","检查") -> OK | E22: 06 §1.1：28 周开发 + 4 周缓冲
A23: 核心线估时 − 周容量（余量） | B23: 0 | C23: =开发进度!$I$18 -> -7 | D23: =IF(C23>=B23,"OK","超出 "&TEXT(B23-C23,"0.0")&"h") -> 超出 7.0h | E23: < 0 表示估时超出周容量，需动用缓冲或砍项
A25: 信息项（非通过 / 失败）
A26: 加工品增值倍率：最小 | C26: =MIN(Recipe!$O$4:$O$14) -> 1.3333333 | E26: 03 文档原写“1.1~1.9 倍”，实际范围见本行与下一行，文档已同步更正
A27: 加工品增值倍率：最大 | C27: =MAX(Recipe!$O$4:$O$14) -> 2.25 | E27: 采集类原料便宜，工坊产物倍率偏高，属预期；M2 经济校准时关注
A29: 脚本模拟参考值（静态，不随配置变化）
A30: 指标 | B30: 值 | E30: 来源
A31: 综合 SR 出率 | B31: 0.1175 | E31: Python 蒙特卡洛 200,000 次，SSR 保底 + SR 每 10 抽保底联动（见 03 §11.4）
A32: 综合 R 出率 | B32: 0.2571 | E32: Python 蒙特卡洛 200,000 次，SSR 保底 + SR 每 10 抽保底联动（见 03 §11.4）
A33: 综合 N 出率 | B33: 0.5978 | E33: Python 蒙特卡洛 200,000 次，SSR 保底 + SR 每 10 抽保底联动（见 03 §11.4）

Sheet 开发进度
A1: 开发进度看板（单人版，依据 06_开发计划）
A3: 起始日期 | B3: 46307 | D3: 黄色底色 = 可编辑输入；开始 / 结束日期、周容量、余量、投入比例均为公式。
A4: 每周投入(h) | B4: 17.5 | D4: 余量 < 0 表示估时超出该里程碑周容量（标红）。
A7: 里程碑 | B7: 名称 | C7: 类型 | D7: 周数 | E7: 开始 | F7: 结束 | G7: 估时(h) | H7: 周容量(h) | I7: 余量(h) | J7: 状态 | K7: 实际投入(h) | L7: 投入/估时
A8: M0 | B8: 预研与灰盒原型 | C8: 核心 | D8: 3 | E8: =$B$3 -> 46307 | F8: =E8+D8*7-1 -> 46327 | G8: 55 | H8: =D8*$B$4 -> 52.5 | I8: =H8-G8 -> -2.5 | J8: 未开始 | K8: 0 | L8: =IF(G8=0,0,K8/G8) -> 0
A9: M1 | B9: 基础框架 | C9: 核心 | D9: 4 | E9: =F8+1 -> 46328 | F9: =E9+D9*7-1 -> 46355 | G9: 75 | H9: =D9*$B$4 -> 70 | I9: =H9-G9 -> -5 | J9: 未开始 | K9: 0 | L9: =IF(G9=0,0,K9/G9) -> 0
A10: M2 | B10: 家园核心玩法 | C10: 核心 | D10: 6 | E10: =F9+1 -> 46356 | F10: =E10+D10*7-1 -> 46397 | G10: 105 | H10: =D10*$B$4 -> 105 | I10: =H10-G10 -> 0 | J10: 未开始 | K10: 0 | L10: =IF(G10=0,0,K10/G10) -> 0
A11: M3 | B11: 垂直切片 | C11: 核心 | D11: 3 | E11: =F10+1 -> 46398 | F11: =E11+D11*7-1 -> 46418 | G11: 52 | H11: =D11*$B$4 -> 52.5 | I11: =H11-G11 -> 0.5 | J11: 未开始 | K11: 0 | L11: =IF(G11=0,0,K11/G11) -> 0
A12: M4 | B12: 广场多人在线 | C12: 核心 | D12: 6 | E12: =F11+1 -> 46419 | F12: =E12+D12*7-1 -> 46460 | G12: 105 | H12: =D12*$B$4 -> 105 | I12: =H12-G12 -> 0 | J12: 未开始 | K12: 0 | L12: =IF(G12=0,0,K12/G12) -> 0
A13: M5 | B13: 抽卡与热更活动 | C13: 核心 | D13: 4 | E13: =F12+1 -> 46461 | F13: =E13+D13*7-1 -> 46488 | G13: 70 | H13: =D13*$B$4 -> 70 | I13: =H13-G13 -> 0 | J13: 未开始 | K13: 0 | L13: =IF(G13=0,0,K13/G13) -> 0
A14: 缓冲 | B14: 欠账 / P1 / 优化 | C14: 核心 | D14: 4 | E14: =F13+1 -> 46489 | F14: =E14+D14*7-1 -> 46516 | G14: 70 | H14: =D14*$B$4 -> 70 | I14: =H14-G14 -> 0 | J14: 未开始 | K14: 0 | L14: =IF(G14=0,0,K14/G14) -> 0
A15: M6 | B15: 作品集收尾 | C15: 核心 | D15: 2 | E15: =F14+1 -> 46517 | F15: =E15+D15*7-1 -> 46530 | G15: 35 | H15: =D15*$B$4 -> 35 | I15: =H15-G15 -> 0 | J15: 未开始 | K15: 0 | L15: =IF(G15=0,0,K15/G15) -> 0
A16: M7 | B16: 移动端适配（Stretch） | C16: Stretch | D16: 5 | E16: =F15+1 -> 46531 | F16: =E16+D16*7-1 -> 46565 | G16: 88 | H16: =D16*$B$4 -> 87.5 | I16: =H16-G16 -> -0.5 | J16: 未开始 | K16: 0 | L16: =IF(G16=0,0,K16/G16) -> 0
A18: 核心线合计 | D18: =SUMIFS(D$8:D$16,$C$8:$C$16,"核心") -> 32 | G18: =SUMIFS(G$8:G$16,$C$8:$C$16,"核心") -> 567 | H18: =SUMIFS(H$8:H$16,$C$8:$C$16,"核心") -> 560 | I18: =SUMIFS(I$8:I$16,$C$8:$C$16,"核心") -> -7 | K18: =SUMIFS(K$8:K$16,$C$8:$C$16,"核心") -> 0 | L18: =IF(G18=0,0,K18/G18) -> 0
A19: Stretch 合计 | D19: =SUMIFS(D$8:D$16,$C$8:$C$16,"Stretch") -> 5 | G19: =SUMIFS(G$8:G$16,$C$8:$C$16,"Stretch") -> 88 | H19: =SUMIFS(H$8:H$16,$C$8:$C$16,"Stretch") -> 87.5 | I19: =SUMIFS(I$8:I$16,$C$8:$C$16,"Stretch") -> -0.5 | K19: =SUMIFS(K$8:K$16,$C$8:$C$16,"Stretch") -> 0 | L19: =IF(G19=0,0,K19/G19) -> 0
A20: 全部合计 | D20: =SUM(D8:D16) -> 37 | G20: =SUM(G8:G16) -> 655 | H20: =SUM(H8:H16) -> 647.5 | I20: =SUM(I8:I16) -> -7.5 | K20: =SUM(K8:K16) -> 0 | L20: =IF(G20=0,0,K20/G20) -> 0
A22: P0 功能完成度
A23: 编号 | B23: 功能 | C23: 对应里程碑 | D23: 状态 | E23: 备注
A24: F01 | B24: 账号登录与存档 | C24: M1 | D24: 未开始
A25: F02 | B25: 背包与物品 | C25: M2 | D25: 未开始
A26: F03 | B26: 种植 | C26: M2 | D26: 未开始
A27: F04 | B27: 采集 | C27: M2 | D27: 未开始
A28: F05 | B28: 加工 | C28: M2 | D28: 未开始
A29: F06 | B29: 订单 | C29: M2 | D29: 未开始
A30: F07 | B30: 成长 | C30: M2 | D30: 未开始
A31: F08 | B31: 家园场景（含装饰） | C31: M2 / M3 | D31: 未开始
A32: F09 | B32: 广场场景 | C32: M4 | D32: 未开始
A33: F10 | B33: 角色外观 | C33: M3 | D33: 未开始
A34: F11 | B34: 抽卡 | C34: M5 | D34: 未开始
A35: F12 | B35: 热更新（代码 + 资源 + 配置） | C35: M1 / M5 | D35: 未开始
A36: F13 | B36: 新手引导 | C36: M3 | D36: 未开始
B37: 已完成 / 总数 | C37: =COUNTIF(D24:D36,"已完成")&" / "&COUNTA(A24:A36) -> 0 / 13 | D37: =COUNTIF(D24:D36,"已完成")/COUNTA(A24:A36) -> 0
A39: 作品集交付物
A40: 编号 | B40: 交付物 | C40: 对应里程碑 | D40: 状态 | E40: 备注
A41: D1 | B41: README（含截图 / GIF / 架构图） | C41: M6 | D41: 未开始
A42: D2 | B42: 演示视频（3~5 分钟） | C42: M6 | D42: 未开始
A43: D3 | B43: 6 份核心文档（回填最终内容） | C43: M6 | D43: 未开始
A44: D4 | B44: 性能记录与优化前后对比 | C44: 缓冲 | D44: 未开始
A45: D5 | B45: 机器人压测报告 | C45: M4 | D45: 未开始
A46: D6 | B46: 素材与开源授权清单 | C46: M6 | D46: 未开始
...

Sheet Global
A1: key | B1: value | C1: desc
A2: string | B2: string | C2: string
A3: Key | B3: 值 | C3: 说明
A4: bag_init_slots | B4: 60 | C4: 背包初始格数
A5: bag_expand_step | B5: 10 | C5: 每次扩容格数
A6: bag_expand_costs | B6: 500;1000;2000;4000;8000 | C6: 第 1~5 次扩容金币（最高 110 格）
A7: stack_default | B7: 99 | C7: 默认堆叠上限
A8: water_ratio | B8: 0.1 | C8: 浇水缩短剩余时间比例（每块地限 1 次）
A9: fertilize_ratio | B9: 0.3 | C9: 施肥缩短剩余时间比例（每块地限 1 次）
A10: speedup_sec_per_gem | B10: 300 | C10: 加工加速：每 300 秒剩余时间 1 钻石，向上取整，最少 1
A11: daily_reset_hour | B11: 0 | C11: 每日刷新时刻（服务器时区 UTC+8）
A12: order_daily_count | B12: 6 | C12: 日常订单数
A13: order_reroll_free | B13: 1 | C13: 每日免费刷新次数
A14: order_reroll_costs | B14: 50;100;150;300 | C14: 第 2 次起刷新费用（第 4 次及以后均为 300）
A15: order_ticket_reward | B15: 3:1;6:1 | C15: 每日完成 3 / 6 条订单各得 1 抽卡券（完成数:券数）
A16: order_all_done_gem | B16: 20 | C16: 每日 6 条全部完成额外钻石
A17: plaza_unlock_level | B17: 7 | C17: 广场开放等级
A18: gacha_unlock_level | B18: 9 | C18: 抽卡开放等级
A19: plaza_line_capacity | B19: 100 | C19: 分线人数上限
A20: chat_interval_sec | B20: 3 | C20: 聊天最短间隔（秒）
A21: new_player_gold | B21: 200 | C21: 新手初始金币
A22: new_player_gem | B22: 300 | C22: 新手初始钻石
A23: new_player_ticket | B23: 5 | C23: 新手初始抽卡券

Sheet Item
A1: id | B1: name | C1: type | D1: stackMax | E1: sellPrice | F1: buyPrice | G1: unlockLevel | H1: desc
A2: int | B2: string | C2: string | D2: int | E2: int | F2: int | G2: int | H2: string
A3: 物品ID | B3: 名称 | C3: 类型 | D3: 堆叠上限(0=不入包) | E3: 出售价(G，0=不可出售) | F3: 购买价(G，0=不在商店出售) | G3: 解锁等级 | H3: 说明
A4: 1001 | B4: 小麦 | C4: crop | D4: 99 | E4: 8 | F4: 0 | G4: 1 | H4: C01 产出
A5: 1002 | B5: 胡萝卜 | C5: crop | D5: 99 | E5: 12 | F5: 0 | G5: 2 | H5: C02 产出
A6: 1003 | B6: 土豆 | C6: crop | D6: 99 | E6: 12 | F6: 0 | G6: 3 | H6: C03 产出
A7: 1004 | B7: 番茄 | C7: crop | D7: 99 | E7: 18 | F7: 0 | G7: 5 | H7: C04 产出
A8: 1005 | B8: 玉米 | C8: crop | D8: 99 | E8: 20 | F8: 0 | G8: 7 | H8: C05 产出
A9: 1006 | B9: 草莓 | C9: crop | D9: 99 | E9: 30 | F9: 0 | G9: 9 | H9: C06 产出
A10: 1007 | B10: 南瓜 | C10: crop | D10: 99 | E10: 40 | F10: 0 | G10: 12 | H10: C07 产出
A11: 2001 | B11: 小麦种子 | C11: seed | D11: 99 | E11: 0 | F11: 10 | G11: 1 | H11: 对应作物 C01
A12: 2002 | B12: 胡萝卜种子 | C12: seed | D12: 99 | E12: 0 | F12: 15 | G12: 2 | H12: 对应作物 C02
A13: 2003 | B13: 土豆种子 | C13: seed | D13: 99 | E13: 0 | F13: 20 | G13: 3 | H13: 对应作物 C03
A14: 2004 | B14: 番茄种子 | C14: seed | D14: 99 | E14: 0 | F14: 30 | G14: 5 | H14: 对应作物 C04
A15: 2005 | B15: 玉米种子 | C15: seed | D15: 99 | E15: 0 | F15: 40 | G15: 7 | H15: 对应作物 C05
... A44: 9101 | B44: 碎片 | C44: currency | D44: 0 | E44: 0 | F44: 0 | G44: 1 | H44: 抽卡重复转化，用于碎片商店

Sheet Crop
A1: id | B1: name | C1: seedId | D1: yieldItemId | E1: unlockLevel | F1: growSec | G1: yieldMin | H1: yieldMax | I1: exp | J1: stageRatio | K1: #seedCost | L1: #sellPrice | M1: #avgYield | N1: #netPerCycle | O1: #netPerHour
A2: string | B2: string | C2: int | D2: int | E2: int | F2: int | G2: int | H2: int | I2: int | J2: string | K2: calc | L2: calc | M2: calc | N2: calc | O2: calc
A3: 作物ID | B3: 名称 | C3: 种子物品ID | D3: 产出物品ID | E3: 解锁等级 | F3: 生长时间(秒) | G3: 产量下限 | H3: 产量上限 | I3: 收获经验 | J3: 4 阶段时间占比(%) | K3: 种子价(G) | L3: 产出单价(G) | M3: 期望产量 | N3: 单轮净收益(G/块) | O3: 每小时净收益(G/块，持续收割)
A4: C01 | B4: 小麦 | C4: 2001 | D4: 1001 | E4: 1 | F4: 120 | G4: 2 | H4: 3 | I4: 2 | J4: 25;25;25;25 | K4: =INDEX(Item!$F$4:$F$44,MATCH(C4,Item!$A$4:$A$44,0)) -> 10 | L4: =INDEX(Item!$E$4:$E$44,MATCH(D4,Item!$A$4:$A$44,0)) -> 8 | M4: =(G4+H4)/2 -> 2.5 | N4: =M4*L4-K4 -> 10 | O4: =N4/(F4/3600) -> 300
A5: C02 | B5: 胡萝卜 | C5: 2002 | D5: 1002 | E5: 2 | F5: 300 | G5: 2 | H5: 3 | I5: 3 | J5: 25;25;25;25 | K5: =INDEX(Item!$F$4:$F$44,MATCH(C5,Item!$A$4:$A$44,0)) -> 15 | L5: =INDEX(Item!$E$4:$E$44,MATCH(D5,Item!$A$4:$A$44,0)) -> 12 | M5: =(G5+H5)/2 -> 2.5 | N5: =M5*L5-K5 -> 15 | O5: =N5/(F5/3600) -> 180
A6: C03 | B6: 土豆 | C6: 2003 | D6: 1003 | E6: 3 | F6: 600 | G6: 3 | H6: 4 | I6: 4 | J6: 25;25;25;25 | K6: =INDEX(Item!$F$4:$F$44,MATCH(C6,Item!$A$4:$A$44,0)) -> 20 | L6: =INDEX(Item!$E$4:$E$44,MATCH(D6,Item!$A$4:$A$44,0)) -> 12 | M6: =(G6+H6)/2 -> 3.5 | N6: =M6*L6-K6 -> 22 | O6: =N6/(F6/3600) -> 132
A7: C04 | B7: 番茄 | C7: 2004 | D7: 1004 | E7: 5 | F7: 1200 | G7: 3 | H7: 4 | I7: 6 | J7: 25;25;25;25 | K7: =INDEX(Item!$F$4:$F$44,MATCH(C7,Item!$A$4:$A$44,0)) -> 30 | L7: =INDEX(Item!$E$4:$E$44,MATCH(D7,Item!$A$4:$A$44,0)) -> 18 | M7: =(G7+H7)/2 -> 3.5 | N7: =M7*L7-K7 -> 33 | O7: =N7/(F7/3600) -> 99
A8: C05 | B8: 玉米 | C8: 2005 | D8: 1005 | E8: 7 | F8: 1800 | G8: 3 | H8: 5 | I8: 8 | J8: 25;25;25;25 | K8: =INDEX(Item!$F$4:$F$44,MATCH(C8,Item!$A$4:$A$44,0)) -> 40 | L8: =INDEX(Item!$E$4:$E$44,MATCH(D8,Item!$A$4:$A$44,0)) -> 20 | M8: =(G8+H8)/2 -> 4 | N8: =M8*L8-K8 -> 40 | O8: =N8/(F8/3600) -> 80
A9: C06 | B9: 草莓 | C9: 2006 | D9: 1006 | E9: 9 | F9: 3600 | G9: 4 | H9: 5 | I9: 12 | J9: 25;25;25;25 | K9: =INDEX(Item!$F$4:$F$44,MATCH(C9,Item!$A$4:$A$44,0)) -> 60 | L9: =INDEX(Item!$E$4:$E$44,MATCH(D9,Item!$A$4:$A$44,0)) -> 30 | M9: =(G9+H9)/2 -> 4.5 | N9: =M9*L9-K9 -> 75 | O9: =N9/(F9/3600) -> 75
A10: C07 | B10: 南瓜 | C10: 2007 | D10: 1007 | E10: 12 | F10: 7200 | G10: 4 | H10: 6 | I10: 18 | J10: 25;25;25;25 | K10: =INDEX(Item!$F$4:$F$44,MATCH(C10,Item!$A$4:$A$44,0)) -> 80 | L10: =INDEX(Item!$E$4:$E$44,MATCH(D10,Item!$A$4:$A$44,0)) -> 40 | M10: =(G10+H10)/2 -> 5 | N10: =M10*L10-K10 -> 120 | O10: =N10/(F10/3600) -> 60

Sheet GatherNode
A1: id | B1: name | C1: toolId | D1: unlockLevel | E1: count | F1: itemId | G1: yieldMin | H1: yieldMax | I1: cooldownSec | J1: rareItemId | K1: rareChance | L1: exp | M1: #avgYield | N1: #expectedValue | O1: #valuePerHour
A2: string | B2: string | C2: int | D2: int | E2: int | F2: int | G2: int | H2: int | I2: int | J2: int | K2: float | L2: int | M2: calc | N2: calc | O2: calc
A3: 采集点ID | B3: 名称 | C3: 所需工具 | D3: 解锁等级 | E3: 家园数量 | F3: 产出物品 | G3: 产量下限 | H3: 产量上限 | I3: 冷却(秒) | J3: 稀有掉落物品 | K3: 基础稀有率 | L3: 采集经验 | M3: 期望产量 | N3: 单次期望价值(G) | O3: 单点每小时价值(G)
A4: G01 | B4: 树木 | C4: 5101 | D4: 1 | E4: 4 | F4: 4001 | G4: 2 | H4: 3 | I4: 600 | J4: 4101 | K4: 0.03 | L4: 1 | M4: =(G4+H4)/2 -> 2.5 | N4: =M4*INDEX(Item!$E$4:$E$44,MATCH(F4,Item!$A$4:$A$44,0))+K4*INDEX(Item!$E$4:$E$44,MATCH(J4,Item!$A$4:$A$44,0)) -> 15.9 | O4: =N4/(I4/3600) -> 95.4
A5: G02 | B5: 浆果丛 | C5: 5103 | D5: 1 | E5: 3 | F5: 4004 | G5: 2 | H5: 4 | I5: 720 | J5: 4104 | K5: 0.03 | L5: 1 | M5: =(G5+H5)/2 -> 3 | N5: =M5*INDEX(Item!$E$4:$E$44,MATCH(F5,Item!$A$4:$A$44,0))+K5*INDEX(Item!$E$4:$E$44,MATCH(J5,Item!$A$4:$A$44,0)) -> 22.05 | O5: =N5/(I5/3600) -> 110.25
A6: G03 | B6: 矿石 | C6: 5102 | D6: 3 | E6: 3 | F6: 4002 | G6: 2 | H6: 3 | I6: 900 | J6: 4102 | K6: 0.03 | L6: 1 | M6: =(G6+H6)/2 -> 2.5 | N6: =M6*INDEX(Item!$E$4:$E$44,MATCH(F6,Item!$A$4:$A$44,0))+K6*INDEX(Item!$E$4:$E$44,MATCH(J6,Item!$A$4:$A$44,0)) -> 16.5 | O6: =N6/(I6/3600) -> 66
A7: G04 | B7: 花丛 | C7: 5103 | D7: 6 | E7: 3 | F7: 4003 | G7: 3 | H7: 4 | I7: 480 | J7: 4103 | K7: 0.03 | L7: 1 | M7: =(G7+H7)/2 -> 3.5 | N7: =M7*INDEX(Item!$E$4:$E$44,MATCH(F7,Item!$A$4:$A$44,0))+K7*INDEX(Item!$E$4:$E$44,MATCH(J7,Item!$A$4:$A$44,0)) -> 18.7 | O7: =N7/(I7/3600) -> 140.25

Sheet Tool
A1: toolId | B1: level | C1: needPlayerLevel | D1: goldCost | E1: mat1_id | F1: mat1_n | G1: mat2_id | H1: mat2_n | I1: yieldBonusMax | J1: rareChance | K1: #materialValue
A2: int | B2: int | C2: int | D2: int | E2: int | F2: int | G2: int | H2: int | I2: int | J2: float | K2: calc
A3: 工具ID | B3: 工具等级 | C3: 玩家等级要求 | D3: 升级金币 | E3: 材料1 ID | F3: 材料1 数量 | G3: 材料2 ID | H3: 材料2 数量 | I3: 产量上限加成 | J3: 稀有掉落率 | K3: 材料价值(G)
A4: 5101 | B4: 1 | C4: 1 | D4: 0 | I4: 0 | J4: 0.03 | K4: =IF(E4="",0,F4*INDEX(Item!$E$4:$E$44,MATCH(E4,Item!$A$4:$A$44,0)))+IF(G4="",0,H4*INDEX(Item!$E$4:$E$44,MATCH(G4,Item!$A$4:$A$44,0))) -> 0
A5: 5101 | B5: 2 | C5: 5 | D5: 300 | E5: 3009 | F5: 5 | I5: 1 | J5: 0.06 | K5: =IF(E5="",0,F5*INDEX(Item!$E$4:$E$44,MATCH(E5,Item!$A$4:$A$44,0)))+IF(G5="",0,H5*INDEX(Item!$E$4:$E$44,MATCH(G5,Item!$A$4:$A$44,0))) -> 175
A6: 5101 | B6: 3 | C6: 10 | D6: 1200 | E6: 3009 | F6: 10 | G6: 3010 | H6: 10 | I6: 2 | J6: 0.1 | K6: =IF(E6="",0,F6*INDEX(Item!$E$4:$E$44,MATCH(E6,Item!$A$4:$A$44,0)))+IF(G6="",0,H6*INDEX(Item!$E$4:$E$44,MATCH(G6,Item!$A$4:$A$44,0))) -> 700
A7: 5102 | B7: 1 | C7: 1 | D7: 0 | I7: 0 | J7: 0.03 | K7: =IF(E7="",0,F7*INDEX(Item!$E$4:$E$44,MATCH(E7,Item!$A$4:$A$44,0)))+IF(G7="",0,H7*INDEX(Item!$E$4:$E$44,MATCH(G7,Item!$A$4:$A$44,0))) -> 0
A8: 5102 | B8: 2 | C8: 5 | D8: 300 | E8: 3009 | F8: 5 | I8: 1 | J8: 0.06 | K8: =IF(E8="",0,F8*INDEX(Item!$E$4:$E$44,MATCH(E8,Item!$A$4:$A$44,0)))+IF(G8="",0,H8*INDEX(Item!$E$4:$E$44,MATCH(G8,Item!$A$4:$A$44,0))) -> 175
A9: 5102 | B9: 3 | C9: 10 | D9: 1200 | E9: 3009 | F9: 10 | G9: 3010 | H9: 10 | I9: 2 | J9: 0.1 | K9: =IF(E9="",0,F9*INDEX(Item!$E$4:$E$44,MATCH(E9,Item!$A$4:$A$44,0)))+IF(G9="",0,H9*INDEX(Item!$E$4:$E$44,MATCH(G9,Item!$A$4:$A$44,0))) -> 700
A10: 5103 | B10: 1 | C10: 1 | D10: 0 | I10: 0 | J10: 0.03 | K10: =IF(E10="",0,F10*INDEX(Item!$E$4:$E$44,MATCH(E10,Item!$A$4:$A$44,0)))+IF(G10="",0,H10*INDEX(Item!$E$4:$E$44,MATCH(G10,Item!$A$4:$A$44,0))) -> 0
A11: 5103 | B11: 2 | C11: 5 | D11: 300 | E11: 3009 | F11: 5 | I11: 1 | J11: 0.06 | K11: =IF(E11="",0,F11*INDEX(Item!$E$4:$E$44,MATCH(E11,Item!$A$4:$A$44,0)))+IF(G11="",0,H11*INDEX(Item!$E$4:$E$44,MATCH(G11,Item!$A$4:$A$44,0))) -> 175
A12: 5103 | B12: 3 | C12: 10 | D12: 1200 | E12: 3009 | F12: 10 | G12: 3010 | H12: 10 | I12: 2 | J12: 0.1 | K12: =IF(E12="",0,F12*INDEX(Item!$E$4:$E$44,MATCH(E12,Item!$A$4:$A$44,0)))+IF(G12="",0,H12*INDEX(Item!$E$4:$E$44,MATCH(G12,Item!$A$4:$A$44,0))) -> 700

Sheet Facility
A1: id | B1: name | C1: unlockLevel | D1: buildGold | E1: category
A2: string | B2: string | C2: int | D2: int | E2: string
A3: 设施ID | B3: 名称 | C3: 解锁等级 | D3: 建造金币 | E3: 可生产类别
A4: F01 | B4: 磨坊 | C4: 2 | D4: 200 | E4: 面粉
A5: F02 | B5: 工坊 | C5: 3 | D5: 400 | E5: 木板;石砖;花束;工具升级
A6: F03 | B6: 烤炉 | C6: 4 | D6: 800 | E6: 面包;玉米饼;草莓蛋糕;南瓜派
A7: F04 | B7: 厨灶 | C7: 4 | D7: 800 | E7: 蔬菜汤;番茄酱;果酱

Sheet FacilityLevel
A1: level | B1: needPlayerLevel | C1: slots | D1: speedFactor | E1: goldCost | F1: mat1_id | G1: mat1_n | H1: mat2_id | I1: mat2_n | J1: mat3_id | K1: mat3_n | L1: #materialValue
A2: int | B2: int | C2: int | D2: float | E2: int | F2: int | G2: int | H2: int | I2: int | J2: int | K2: int | L2: calc
A3: 设施等级 | B3: 玩家等级要求 | C3: 槽位数 | D3: 生产时间倍率 | E3: 升级金币 | F3: 材料1 ID | G3: 材料1 数量 | H3: 材料2 ID | I3: 材料2 数量 | J3: 材料3 ID | K3: 材料3 数量 | L3: 材料价值(G)
A4: 1 | B4: 1 | C4: 2 | D4: 1 | E4: 0 | L4: =IF(F4="",0,G4*INDEX(Item!$E$4:$E$44,MATCH(F4,Item!$A$4:$A$44,0)))+IF(H4="",0,I4*INDEX(Item!$E$4:$E$44,MATCH(H4,Item!$A$4:$A$44,0)))+IF(J4="",0,K4*INDEX(Item!$E$4:$E$44,MATCH(J4,Item!$A$4:$A$44,0))) -> 0
A5: 2 | B5: 8 | C5: 3 | D5: 0.9 | E5: 1500 | F5: 3009 | G5: 10 | H5: 3010 | I5: 10 | L5: =IF(F5="",0,G5*INDEX(Item!$E$4:$E$44,MATCH(F5,Item!$A$4:$A$44,0)))+IF(H5="",0,I5*INDEX(Item!$E$4:$E$44,MATCH(H5,Item!$A$4:$A$44,0)))+IF(J5="",0,K5*INDEX(Item!$E$4:$E$44,MATCH(J5,Item!$A$4:$A$44,0))) -> 700
A6: 3 | B6: 15 | C6: 4 | D6: 0.8 | E6: 6000 | F6: 3009 | G6: 30 | H6: 3010 | I6: 30 | J6: 4102 | K6: 3 | L6: =IF(F6="",0,G6*INDEX(Item!$E$4:$E$44,MATCH(F6,Item!$A$4:$A$44,0)))+IF(H6="",0,I6*INDEX(Item!$E$4:$E$44,MATCH(H6,Item!$A$4:$A$44,0)))+IF(J6="",0,K6*INDEX(Item!$E$4:$E$44,MATCH(J6,Item!$A$4:$A$44,0))) -> 2250

Sheet Recipe
A1: id | B1: name | C1: facilityId | D1: unlockLevel | E1: in1_id | F1: in1_n | G1: in2_id | H1: in2_n | I1: out_id | J1: out_n | K1: durationSec | L1: exp | M1: #inputValue | N1: #outputValue | O1: #valueAddRatio | P1: #gainPerMin
A2: string | B2: string | C2: string | D2: int | E2: int | F2: int | G2: int | H2: int | I2: int | J2: int | K2: int | L2: int | M2: calc | N2: calc | O2: calc | P2: calc
A3: 配方ID | B3: 配方 | C3: 设施 | D3: 解锁等级 | E3: 材料1 ID | F3: 材料1 数量 | G3: 材料2 ID | H3: 材料2 数量 | I3: 产物 ID | J3: 产物数量 | K3: 耗时(秒) | L3: 领取经验 | M3: 材料价值(G) | N3: 产物价值(G) | O3: 增值倍率 | P3: 每分钟增值(G)
A4: RC001 | B4: 面粉 | C4: F01 | D4: 2 | E4: 1001 | F4: 3 | I4: 3001 | J4: 1 | K4: 60 | L4: 1 | M4: =F4*INDEX(Item!$E$4:$E$44,MATCH(E4,Item!$A$4:$A$44,0))+IF(G4="",0,H4*INDEX(Item!$E$4:$E$44,MATCH(G4,Item!$A$4:$A$44,0))) -> 24 | N4: =J4*INDEX(Item!$E$4:$E$44,MATCH(I4,Item!$A$4:$A$44,0)) -> 32 | O4: =N4/M4 -> 1.3333333 | P4: =(N4-M4)/(K4/60) -> 8
A5: RC009 | B5: 木板 | C5: F02 | D5: 3 | E5: 4001 | F5: 3 | I5: 3009 | J5: 1 | K5: 90 | L5: 2 | M5: =F5*INDEX(Item!$E$4:$E$44,MATCH(E5,Item!$A$4:$A$44,0))+IF(G5="",0,H5*INDEX(Item!$E$4:$E$44,MATCH(G5,Item!$A$4:$A$44,0))) -> 18 | N5: =J5*INDEX(Item!$E$4:$E$44,MATCH(I5,Item!$A$4:$A$44,0)) -> 35 | O5: =N5/M5 -> 1.9444444 | P5: =(N5-M5)/(K5/60) -> 11.333333
A6: RC010 | B6: 石砖 | C6: F02 | D6: 3 | E6: 4002 | F6: 3 | I6: 3010 | J6: 1 | K6: 90 | L6: 2 | M6: =F6*INDEX(Item!$E$4:$E$44,MATCH(E6,Item!$A$4:$A$44,0))+IF(G6="",0,H6*INDEX(Item!$E$4:$E$44,MATCH(G6,Item!$A$4:$A$44,0))) -> 18 | N6: =J6*INDEX(Item!$E$4:$E$44,MATCH(I6,Item!$A$4:$A$44,0)) -> 35 | O6: =N6/M6 -> 1.9444444 | P6: =(N6-M6)/(K6/60) -> 11.333333
A7: RC002 | B7: 面包 | C7: F03 | D7: 4 | E7: 3001 | F7: 2 | I7: 3002 | J7: 1 | K7: 120 | L7: 3 | M7: =F7*INDEX(Item!$E$4:$E$44,MATCH(E7,Item!$A$4:$A$44,0))+IF(G7="",0,H7*INDEX(Item!$E$4:$E$44,MATCH(G7,Item!$A$4:$A$44,0))) -> 64 | N7: =J7*INDEX(Item!$E$4:$E$44,MATCH(I7,Item!$A$4:$A$44,0)) -> 90 | O7: =N7/M7 -> 1.40625 | P7: =(N7-M7)/(K7/60) -> 13
A8: RC003 | B8: 蔬菜汤 | C8: F04 | D8: 4 | E8: 1002 | F8: 2 | G8: 1003 | H8: 2 | I8: 3003 | J8: 1 | K8: 180 | L8: 4 | M8: =F8*INDEX(Item!$E$4:$E$44,MATCH(E8,Item!$A$4:$A$44,0))+IF(G8="",0,H8*INDEX(Item!$E$4:$E$44,MATCH(G8,Item!$A$4:$A$44,0))) -> 48 | N8: =J8*INDEX(Item!$E$4:$E$44,MATCH(I8,Item!$A$4:$A$44,0)) -> 80 | O8: =N8/M8 -> 1.6666667 | P8: =(N8-M8)/(K8/60) -> 10.666667
A9: RC004 | B9: 果酱 | C9: F04 | D9: 4 | E9: 4004 | F9: 3 | I9: 3005 | J9: 1 | K9: 150 | L9: 3 | M9: =F9*INDEX(Item!$E$4:$E$44,MATCH(E9,Item!$A$4:$A$44,0))+IF(G9="",0,H9*INDEX(Item!$E$4:$E$44,MATCH(G9,Item!$A$4:$A$44,0))) -> 21 | N9: =J9*INDEX(Item!$E$4:$E$44,MATCH(I9,Item!$A$4:$A$44,0)) -> 45 | O9: =N9/M9 -> 2.1428571 | P9: =(N9-M9)/(K9/60) -> 9.6
A10: RC005 | B10: 番茄酱 | C10: F04 | D10: 5 | E10: 1004 | F10: 3 | I10: 3004 | J10: 1 | K10: 180 | L10: 5 | M10: =F10*INDEX(Item!$E$4:$E$44,MATCH(E10,Item!$A$4:$A$44,0))+IF(G10="",0,H10*INDEX(Item!$E$4:$E$44,MATCH(G10,Item!$A$4:$A$44,0))) -> 54 | N10: =J10*INDEX(Item!$E$4:$E$44,MATCH(I10,Item!$A$4:$A$44,0)) -> 85 | O10: =N10/M10 -> 1.5740741 | P10: =(N10-M10)/(K10/60) -> 10.333333
A11: RC011 | B11: 花束 | C11: F02 | D11: 6 | E11: 4003 | F11: 4 | I11: 3011 | J11: 1 | K11: 120 | L11: 3 | M11: =F11*INDEX(Item!$E$4:$E$44,MATCH(E11,Item!$A$4:$A$44,0))+IF(G11="",0,H11*INDEX(Item!$E$4:$E$44,MATCH(G11,Item!$A$4:$A$44,0))) -> 20 | N11: =J11*INDEX(Item!$E$4:$E$44,MATCH(I11,Item!$A$4:$A$44,0)) -> 45 | O11: =N11/M11 -> 2.25 | P11: =(N11-M11)/(K11/60) -> 12.5
A12: RC006 | B12: 玉米饼 | C12: F03 | D12: 7 | E12: 1005 | F12: 2 | G12: 3001 | H12: 1 | I12: 3006 | J12: 1 | K12: 300 | L12: 8 | M12: =F12*INDEX(Item!$E$4:$E$44,MATCH(E12,Item!$A$4:$A$44,0))+IF(G12="",0,H12*INDEX(Item!$E$4:$E$44,MATCH(G12,Item!$A$4:$A$44,0))) -> 72 | N12: =J12*INDEX(Item!$E$4:$E$44,MATCH(I12,Item!$A$4:$A$44,0)) -> 130 | O12: =N12/M12 -> 1.8055556 | P12: =(N12-M12)/(K12/60) -> 11.6
A13: RC007 | B13: 草莓蛋糕 | C13: F03 | D13: 9 | E13: 3001 | F13: 2 | G13: 1006 | H13: 3 | I13: 3007 | J13: 1 | K13: 600 | L13: 15 | M13: =F13*INDEX(Item!$E$4:$E$44,MATCH(E13,Item!$A$4:$A$44,0))+IF(G13="",0,H13*INDEX(Item!$E$4:$E$44,MATCH(G13,Item!$A$4:$A$44,0))) -> 154 | N13: =J13*INDEX(Item!$E$4:$E$44,MATCH(I13,Item!$A$4:$A$44,0)) -> 260 | O13: =N13/M13 -> 1.6883117 | P13: =(N13-M13)/(K13/60) -> 10.6
A14: RC008 | B14: 南瓜派 | C14: F03 | D14: 12 | E14: 1007 | F14: 1 | G14: 3001 | H14: 2 | I14: 3008 | J14: 1 | K14: 900 | L14: 22 | M14: =F14*INDEX(Item!$E$4:$E$44,MATCH(E14,Item!$A$4:$A$44,0))+IF(G14="",0,H14*INDEX(Item!$E$4:$E$44,MATCH(G14,Item!$A$4:$A$44,0))) -> 104 | N14: =J14*INDEX(Item!$E$4:$E$44,MATCH(I14,Item!$A$4:$A$44,0)) -> 190 | O14: =N14/M14 -> 1.8269231 | P14: =(N14-M14)/(K14/60) -> 5.7333333

Sheet Level
A1: level | B1: needExp | C1: #cumExp
A2: int | B2: int | C2: calc
A3: 当前等级 | B3: 升至下一级所需经验 | C3: 累计经验 | F3: 参数 | G3: 值 | H3: 说明
A4: 1 | B4: =$G$4+$G$5*(A4-1)+$G$6*(A4-1)^2 -> 20 | C4: =SUM($B$4:B4) -> 20 | F4: a | G4: 20 | H4: need(L) = a + b×(L−1) + c×(L−1)²
A5: 2 | B5: =$G$4+$G$5*(A5-1)+$G$6*(A5-1)^2 -> 35 | C5: =SUM($B$4:B5) -> 55 | F5: b | G5: 12 | H5: 一次项系数
A6: 3 | B6: =$G$4+$G$5*(A6-1)+$G$6*(A6-1)^2 -> 56 | C6: =SUM($B$4:B6) -> 111 | F6: c | G6: 3 | H6: 二次项系数
A7: 4 | B7: =$G$4+$G$5*(A7-1)+$G$6*(A7-1)^2 -> 83 | C7: =SUM($B$4:B7) -> 194 | F7: maxLevel | G7: 20 | H7: 最高等级（MVP）
A8: 5 | B8: =$G$4+$G$5*(A8-1)+$G$6*(A8-1)^2 -> 116 | C8: =SUM($B$4:B8) -> 310
A9: 6 | B9: =$G$4+$G$5*(A9-1)+$G$6*(A9-1)^2 -> 155 | C9: =SUM($B$4:B9) -> 465 | F9: 黄色底色 = 可调参数；改后 needExp / 累计经验自动更新。
A10: 7 | B10: =$G$4+$G$5*(A10-1)+$G$6*(A10-1)^2 -> 200 | C10: =SUM($B$4:B10) -> 665
A11: 8 | B11: =$G$4+$G$5*(A11-1)+$G$6*(A11-1)^2 -> 251 | C11: =SUM($B$4:B11) -> 916
A12: 9 | B12: =$G$4+$G$5*(A12-1)+$G$6*(A12-1)^2 -> 308 | C12: =SUM($B$4:B12) -> 1224
A13: 10 | B13: =$G$4+$G$5*(A13-1)+$G$6*(A13-1)^2 -> 371 | C13: =SUM($B$4:B13) -> 1595
A14: 11 | B14: =$G$4+$G$5*(A14-1)+$G$6*(A14-1)^2 -> 440 | C14: =SUM($B$4:B14) -> 2035
A15: 12 | B15: =$G$4+$G$5*(A15-1)+$G$6*(A15-1)^2 -> 515 | C15: =SUM($B$4:B15) -> 2550
A16: 13 | B16: =$G$4+$G$5*(A16-1)+$G$6*(A16-1)^2 -> 596 | C16: =SUM($B$4:B16) -> 3146
A17: 14 | B17: =$G$4+$G$5*(A17-1)+$G$6*(A17-1)^2 -> 683 | C17: =SUM($B$4:B17) -> 3829
A18: 15 | B18: =$G$4+$G$5*(A18-1)+$G$6*(A18-1)^2 -> 776 | C18: =SUM($B$4:B18) -> 4605
A19: 16 | B19: =$G$4+$G$5*(A19-1)+$G$6*(A19-1)^2 -> 875 | C19: =SUM($B$4:B19) -> 5480
A20: 17 | B20: =$G$4+$G$5*(A20-1)+$G$6*(A20-1)^2 -> 980 | C20: =SUM($B$4:B20) -> 6460
A21: 18 | B21: =$G$4+$G$5*(A21-1)+$G$6*(A21-1)^2 -> 1091 | C21: =SUM($B$4:B21) -> 7551
A22: 19 | B22: =$G$4+$G$5*(A22-1)+$G$6*(A22-1)^2 -> 1208 | C22: =SUM($B$4:B22) -> 8759

Sheet Plot
A1: stage | B1: needPlayerLevel | C1: totalPlots | D1: unlockGold | E1: #newPlots | F1: #cumGold
A2: int | B2: int | C2: int | D2: int | E2: calc | F2: calc
A3: 阶段(0=初始) | B3: 玩家等级 | C3: 地块总数 | D3: 本次解锁金币 | E3: 本次新增地块 | F3: 累计金币
A4: 0 | B4: 1 | C4: 6 | D4: 0 | E4: =C4 -> 6 | F4: =SUM($D$4:D4) -> 0
A5: 1 | B5: 3 | C5: 9 | D5: 300 | E5: =C5-C4 -> 3 | F5: =SUM($D$4:D5) -> 300
A6: 2 | B6: 5 | C6: 12 | D6: 800 | E6: =C6-C5 -> 3 | F6: =SUM($D$4:D6) -> 1100
A7: 3 | B7: 8 | C7: 16 | D7: 2000 | E7: =C7-C6 -> 4 | F7: =SUM($D$4:D7) -> 3100
A8: 4 | B8: 12 | C8: 20 | D8: 5000 | E8: =C8-C7 -> 4 | F8: =SUM($D$4:D8) -> 8100
A9: 5 | B9: 16 | C9: 24 | D9: 12000 | E9: =C9-C8 -> 4 | F9: =SUM($D$4:D9) -> 20100

Sheet OrderRule
A1: key | B1: value | C1: desc
A2: string | B2: string | C2: string
A3: Key | B3: 值 | C3: 说明
A4: k_easy | B4: 1.3 | C4: 金币系数：简单（1 项）
A5: k_normal | B5: 1.4 | C5: 金币系数：普通（2 项）
A6: k_hard | B6: 1.6 | C6: 金币系数：困难（3 项）
A7: exp_coef | B7: 0.25 | C7: 经验 = max(exp_min, round(V × exp_coef))
A8: exp_min | B8: 5 | C8: 订单经验下限
A9: rare_chance | B9: 0.1 | C9: “稀有加成”概率
A10: rare_gold_mult | B10: 1.5 | C10: 稀有加成：金币倍率
A11: daily_count | B11: 6 | C11: 每日订单数
A12: diff_ratio | B12: 3:2:1 | C12: 简单 : 普通 : 困难 比例
A13: weight_lv1_3 | B13: 原料60%;加工品40% | C13: Lv1~3 物品权重
A14: weight_lv4_plus | B14: 原料40%;加工品60% | C14: Lv4 起 物品权重
A15: raw_count | B15: 2~6 | C15: 原料数量范围（sell ≥ 30 时 2~3）
A16: product_count | B16: 1~3 | C16: 加工品数量范围（sell ≥ 130 时 1~2）
A17: min_instant_orders | B17: 2 | C17: 至少 N 条订单为玩家当前可立即完成

Sheet OrderCalc
A1: 订单奖励计算器（读取 Item 售价与 OrderRule 参数）
A2: 用法：在前 6 个蓝色输入列填物品 ID / 数量与难度（1 简单 / 2 普通 / 3 困难），后 5 列为公式。留空 H 列则整行不计算。
A4: 订单描述 | B4: item1_id | C4: n1 | D4: item2_id | E4: n2 | F4: item3_id | G4: n3 | H4: 难度 | I4: V 总价值(G) | J4: 系数 k | K4: 金币奖励 | L4: 经验奖励 | M4: 稀有加成金币
A5: 小麦 ×6 | B5: 1001 | C5: 6 | H5: 1 | I5: =IF(H5="","",IF(B5="",0,C5*INDEX(Item!$E$4:$E$44,MATCH(B5,Item!$A$4:$A$44,0)))+IF(D5="",0,E5*INDEX(Item!$E$4:$E$44,MATCH(D5,Item!$A$4:$A$44,0)))+IF(F5="",0,G5*INDEX(Item!$E$4:$E$44,MATCH(F5,Item!$A$4:$A$44,0)))) -> 48 | J5: =IF(H5="","",CHOOSE(H5,OrderRule!$B$4,OrderRule!$B$5,OrderRule!$B$6)) -> 1.3 | K5: =IF(H5="","",ROUND(I5*J5,0)) -> 62 | L5: =IF(H5="","",MAX(OrderRule!$B$8,ROUND(I5*OrderRule!$B$7,0))) -> 12 | M5: =IF(H5="","",ROUND(K5*OrderRule!$B$10,0)) -> 93
A6: 面包 ×2 | B6: 3002 | C6: 2 | H6: 2 | I6: =IF(H6="","",IF(B6="",0,C6*INDEX(Item!$E$4:$E$44,MATCH(B6,Item!$A$4:$A$44,0)))+IF(D6="",0,E6*INDEX(Item!$E$4:$E$44,MATCH(D6,Item!$A$4:$A$44,0)))+IF(F6="",0,G6*INDEX(Item!$E$4:$E$44,MATCH(F6,Item!$A$4:$A$44,0)))) -> 180 | J6: =IF(H6="","",CHOOSE(H6,OrderRule!$B$4,OrderRule!$B$5,OrderRule!$B$6)) -> 1.4 | K6: =IF(H6="","",ROUND(I6*J6,0)) -> 252 | L6: =IF(H6="","",MAX(OrderRule!$B$8,ROUND(I6*OrderRule!$B$7,0))) -> 45 | M6: =IF(H6="","",ROUND(K6*OrderRule!$B$10,0)) -> 378
A7: 蔬菜汤 + 番茄酱 + 花束 ×2 | B7: 3003 | C7: 1 | D7: 3004 | E7: 1 | F7: 3011 | G7: 2 | H7: 3 | I7: =IF(H7="","",IF(B7="",0,C7*INDEX(Item!$E$4:$E$44,MATCH(B7,Item!$A$4:$A$44,0)))+IF(D7="",0,E7*INDEX(Item!$E$4:$E$44,MATCH(D7,Item!$A$4:$A$44,0)))+IF(F7="",0,G7*INDEX(Item!$E$4:$E$44,MATCH(F7,Item!$A$4:$A$44,0)))) -> 255 | J7: =IF(H7="","",CHOOSE(H7,OrderRule!$B$4,OrderRule!$B$5,OrderRule!$B$6)) -> 1.6 | K7: =IF(H7="","",ROUND(I7*J7,0)) -> 408 | L7: =IF(H7="","",MAX(OrderRule!$B$8,ROUND(I7*OrderRule!$B$7,0))) -> 64 | M7: =IF(H7="","",ROUND(K7*OrderRule!$B$10,0)) -> 612
A8: 草莓蛋糕 ×2 + 南瓜派 + 玉米饼 | B8: 3007 | C8: 2 | D8: 3008 | E8: 1 | F8: 3006 | G8: 1 | H8: 3 | I8: =IF(H8="","",IF(B8="",0,C8*INDEX(Item!$E$4:$E$44,MATCH(B8,Item!$A$4:$A$44,0)))+IF(D8="",0,E8*INDEX(Item!$E$4:$E$44,MATCH(D8,Item!$A$4:$A$44,0)))+IF(F8="",0,G8*INDEX(Item!$E$4:$E$44,MATCH(F8,Item!$A$4:$A$44,0)))) -> 840 | J8: =IF(H8="","",CHOOSE(H8,OrderRule!$B$4,OrderRule!$B$5,OrderRule!$B$6)) -> 1.6 | K8: =IF(H8="","",ROUND(I8*J8,0)) -> 1344 | L8: =IF(H8="","",MAX(OrderRule!$B$8,ROUND(I8*OrderRule!$B$7,0))) -> 210 | M8: =IF(H8="","",ROUND(K8*OrderRule!$B$10,0)) -> 2016
I9: =IF(H9="","",IF(B9="",0,C9*INDEX(Item!$E$4:$E$44,MATCH(B9,Item!$A$4:$A$44,0)))+IF(D9="",0,E9*INDEX(Item!$E$4:$E$44,MATCH(D9,Item!$A$4:$A$44,0)))+IF(F9="",0,G9*INDEX(Item!$E$4:$E$44,MATCH(F9,Item!$A$4:$A$44,0)))) | J9: =IF(H9="","",CHOOSE(H9,OrderRule!$B$4,OrderRule!$B$5,OrderRule!$B$6)) | K9: =IF(H9="","",ROUND(I9*J9,0)) | L9: =IF(H9="","",MAX(OrderRule!$B$8,ROUND(I9*OrderRule!$B$7,0))) | M9: =IF(H9="","",ROUND(K9*OrderRule!$B$10,0))
I10: =IF(H10="","",IF(B10="",0,C10*INDEX(Item!$E$4:$E$44,MATCH(B10,Item!$A$4:$A$44,0)))+IF(D10="",0,E10*INDEX(Item!$E$4:$E$44,MATCH(D10,Item!$A$4:$A$44,0)))+IF(F10="",0,G10*INDEX(Item!$E$4:$E$44,MATCH(F10,Item!$A$4:$A$44,0)))) | J10: =IF(H10="","",CHOOSE(H10,OrderRule!$B$4,OrderRule!$B$5,OrderRule!$B$6)) | K10: =IF(H10="","",ROUND(I10*J10,0)) | L10: =IF(H10="","",MAX(OrderRule!$B$8,ROUND(I10*OrderRule!$B$7,0))) | M10: =IF(H10="","",ROUND(K10*OrderRule!$B$10,0))
I11: =IF(H11="","",IF(B11="",0,C11*INDEX(Item!$E$4:$E$44,MATCH(B11,Item!$A$4:$A$44,0)))+IF(D11="",0,E11*INDEX(Item!$E$4:$E$44,MATCH(D11,Item!$A$4:$A$44,0)))+IF(F11="",0,G11*INDEX(Item!$E$4:$E$44,MATCH(F11,Item!$A$4:$A$44,0)))) | J11: =IF(H11="","",CHOOSE(H11,OrderRule!$B$4,OrderRule!$B$5,OrderRule!$B$6)) | K11: =IF(H11="","",ROUND(I11*J11,0)) | L11: =IF(H11="","",MAX(OrderRule!$B$8,ROUND(I11*OrderRule!$B$7,0))) | M11: =IF(H11="","",ROUND(K11*OrderRule!$B$10,0))
I12: =IF(H12="","",IF(B12="",0,C12*INDEX(Item!$E$4:$E$44,MATCH(B12,Item!$A$4:$A$44,0)))+IF(D12="",0,E12*INDEX(Item!$E$4:$E$44,MATCH(D12,Item!$A$4:$A$44,0)))+IF(F12="",0,G12*INDEX(Item!$E$4:$E$44,MATCH(F12,Item!$A$4:$A$44,0)))) | J12: =IF(H12="","",CHOOSE(H12,OrderRule!$B$4,OrderRule!$B$5,OrderRule!$B$6)) | K12: =IF(H12="","",ROUND(I12*J12,0)) | L12: =IF(H12="","",MAX(OrderRule!$B$8,ROUND(I12*OrderRule!$B$7,0))) | M12: =IF(H12="","",ROUND(K12*OrderRule!$B$10,0))
I13: =IF(H13="","",IF(B13="",0,C13*INDEX(Item!$E$4:$E$44,MATCH(B13,Item!$A$4:$A$44,0)))+IF(D13="",0,E13*INDEX(Item!$E$4:$E$44,MATCH(D13,Item!$A$4:$A$44,0)))+IF(F13="",0,G13*INDEX(Item!$E$4:$E$44,MATCH(F13,Item!$A$4:$A$44,0)))) | J13: =IF(H13="","",CHOOSE(H13,OrderRule!$B$4,OrderRule!$B$5,OrderRule!$B$6)) | K13: =IF(H13="","",ROUND(I13*J13,0)) | L13: =IF(H13="","",MAX(OrderRule!$B$8,ROUND(I13*OrderRule!$B$7,0))) | M13: =IF(H13="","",ROUND(K13*OrderRule!$B$10,0))
I14: =IF(H14="","",IF(B14="",0,C14*INDEX(Item!$E$4:$E$44,MATCH(B14,Item!$A$4:$A$44,0)))+IF(D14="",0,E14*INDEX(Item!$E$4:$E$44,MATCH(D14,Item!$A$4:$A$44,0)))+IF(F14="",0,G14*INDEX(Item!$E$4:$E$44,MATCH(F14,Item!$A$4:$A$44,0)))) | J14: =IF(H14="","",CHOOSE(H14,OrderRule!$B$4,OrderRule!$B$5,OrderRule!$B$6)) | K14: =IF(H14="","",ROUND(I14*J14,0)) | L14: =IF(H14="","",MAX(OrderRule!$B$8,ROUND(I14*OrderRule!$B$7,0))) | M14: =IF(H14="","",ROUND(K14*OrderRule!$B$10,0))

Sheet Furniture
A1: id | B1: name | C1: sizeW | D1: sizeH | E1: price | F1: unlockLevel | G1: comfort | H1: #area | I1: #goldPerComfort
A2: int | B2: string | C2: int | D2: int | E2: int | F2: int | G2: int | H2: calc | I2: calc
A3: 家具ID | B3: 名称 | C3: 占格宽 | D3: 占格高 | E3: 价格(G) | F3: 解锁等级 | G3: 舒适度 | H3: 占格面积 | I3: 每点舒适度价格(G)
A4: 6001 | B4: 木栅栏 | C4: 1 | D4: 1 | E4: 30 | F4: 6 | G4: 1 | H4: =C4*D4 -> 1 | I4: =E4/G4 -> 30
A5: 6002 | B5: 花盆 | C5: 1 | D5: 1 | E5: 50 | F5: 6 | G5: 2 | H5: =C5*D5 -> 1 | I5: =E5/G5 -> 25
A6: 6003 | B6: 长椅 | C6: 2 | D6: 1 | E6: 120 | F6: 6 | G6: 3 | H6: =C6*D6 -> 2 | I6: =E6/G6 -> 40
A7: 6004 | B7: 路灯 | C7: 1 | D7: 1 | E7: 150 | F7: 6 | G7: 3 | H7: =C7*D7 -> 1 | I7: =E7/G7 -> 50
A8: 6005 | B8: 小树 | C8: 2 | D8: 2 | E8: 200 | F8: 8 | G8: 4 | H8: =C8*D8 -> 4 | I8: =E8/G8 -> 50
A9: 6006 | B9: 石桌椅 | C9: 2 | D9: 2 | E9: 300 | F9: 8 | G9: 5 | H9: =C9*D9 -> 4 | I9: =E9/G9 -> 60
A10: 6007 | B10: 地毯 | C10: 3 | D10: 2 | E10: 250 | F10: 8 | G10: 4 | H10: =C10*D10 -> 6 | I10: =E10/G10 -> 62.5
A11: 6008 | B11: 秋千 | C11: 2 | D11: 2 | E11: 600 | F11: 12 | G11: 8 | H11: =C11*D11 -> 4 | I11: =E11/G11 -> 75
A12: 6009 | B12: 凉亭 | C12: 3 | D12: 3 | E12: 1500 | F12: 12 | G12: 15 | H12: =C12*D12 -> 9 | I12: =E12/G12 -> 100
A13: 6010 | B13: 喷泉 | C13: 3 | D13: 3 | E13: 3000 | F13: 16 | G13: 25 | H13: =C13*D13 -> 9 | I13: =E13/G13 -> 120

Sheet AvatarItem
A1: id | B1: name | C1: part | D1: rarity | E1: source | F1: price | G1: poolGroup | H1: isUp
A2: int | B2: string | C2: string | D2: string | E2: string | F2: int | G2: string | H2: int
A3: 外观ID | B3: 名称 | C3: 部位(hair/top/bottom/shoes/hat/acc/dress) | D3: 稀有度 | E3: 来源 | F3: 商店价(G) | G3: 所属(常驻/P02) | H3: 是否限时池UP(0/1)
A4: 7001 | B4: 短发·黑 | C4: hair | D4: N | E4: 初始 | G4: 常驻 | H4: 0
A5: 7002 | B5: 双马尾·棕 | C5: hair | D5: N | E5: 商店 | F5: 200 | G5: 常驻 | H5: 0
A6: 7003 | B6: 卷发·栗 | C6: hair | D6: R | E6: 抽卡 | G6: 常驻 | H6: 0
A7: 7004 | B7: 长发·樱粉 | C7: hair | D7: SR | E7: 抽卡 | G7: 常驻 | H7: 0
A8: 7005 | B8: 星光长发 | C8: hair | D8: SSR | E8: 抽卡 | G8: 常驻 | H8: 0
A9: 7006 | B9: 白色 T 恤 | C9: top | D9: N | E9: 初始 | G9: 常驻 | H9: 0
A10: 7007 | B10: 条纹衫 | C10: top | D10: N | E10: 商店 | F10: 250 | G10: 常驻 | H10: 0
A11: 7008 | B11: 针织背心 | C11: top | D11: R | E11: 抽卡 | G11: 常驻 | H11: 0
A12: 7009 | B12: 工装外套 | C12: top | D12: R | E12: 抽卡 | G12: 常驻 | H12: 0
A13: 7010 | B13: 刺绣衬衫 | C13: top | D13: SR | E13: 抽卡 | G13: 常驻 | H13: 0
A14: 7011 | B14: 牛仔短裤 | C14: bottom | D14: N | E14: 初始 | G14: 常驻 | H14: 0
A15: 7012 | B15: 格子裙 | C15: bottom | D15: N | E15: 商店 | F15: 250 | G15: 常驻 | H15: 0
A16: 7013 | B16: 工装长裤 | C16: bottom | D16: R | E16: 抽卡 | G16: 常驻 | H16: 0
A17: 7014 | B17: 百褶裙 | C17: bottom | D17: R | E17: 抽卡 | G17: 常驻 | H17: 0
A18: 7015 | B18: 灯笼裤 | C18: bottom | D18: SR | E18: 抽卡 | G18: 常驻 | H18: 0
A19: 7016 | B19: 帆布鞋 | C19: shoes | D19: N | E19: 初始 | G19: 常驻 | H19: 0
A20: 7017 | B20: 小皮靴 | C20: shoes | D20: N | E20: 商店 | F20: 300 | G20: 常驻 | H20: 0
A21: 7018 | B21: 绒毛靴 | C21: shoes | D21: R | E21: 抽卡 | G21: 常驻 | H21: 0
A22: 7019 | B22: 云朵运动鞋 | C22: shoes | D22: SR | E22: 抽卡 | G22: 常驻 | H22: 0
A23: 7020 | B23: 无帽 | C23: hat | D23: N | E23: 初始 | G23: 常驻 | H23: 0
A24: 7021 | B24: 贝雷帽 | C24: hat | D24: N | E24: 商店 | F24: 300 | G24: 常驻 | H24: 0
A25: 7022 | B25: 渔夫帽 | C25: hat | D25: R | E25: 抽卡 | G25: 常驻 | H25: 0
A26: 7023 | B26: 兔耳发箍 | C26: hat | D26: R | E26: 抽卡 | G26: 常驻 | H26: 0
A27: 7024 | B27: 月光皇冠 | C27: hat | D27: SSR | E27: 抽卡 | G27: 常驻 | H27: 0
A28: 7025 | B28: 无饰品 | C28: acc | D28: N | E28: 初始 | G28: 常驻 | H28: 0
A29: 7026 | B29: 圆框眼镜 | C29: acc | D29: N | E29: 商店 | F29: 200 | G29: 常驻 | H29: 0
A30: 7027 | B30: 小背包 | C30: acc | D30: R | E30: 抽卡 | G30: 常驻 | H30: 0
A31: 7028 | B31: 蝴蝶结 | C31: acc | D31: R | E31: 抽卡 | G31: 常驻 | H31: 0
A32: 7029 | B32: 云朵翅膀 | C32: acc | D32: SR | E32: 抽卡 | G32: 常驻 | H32: 0
A33: 7030 | B33: 星河长裙 | C33: dress | D33: SSR | E33: 抽卡 | G33: 常驻 | H33: 0
A34: 7101 | B34: 春日野餐·连衣裙 | C34: dress | D34: SSR | E34: 抽卡 | G34: P02 | H34: 1
A35: 7102 | B35: 春日野餐·草帽 | C35: hat | D35: SSR | E35: 抽卡 | G35: P02 | H35: 1
A36: 7103 | B36: 春日野餐·格纹披肩 | C36: acc | D36: SR | E36: 抽卡 | G36: P02 | H36: 0
A37: 7104 | B37: 春日野餐·编织篮 | C37: acc | D37: SR | E37: 抽卡 | G37: P02 | H37: 0
A38: 7105 | B38: 春日野餐·凉鞋 | C38: shoes | D38: R | E38: 抽卡 | G38: P02 | H38: 0
A39: 7106 | B39: 春日野餐·丝带 | C39: hair | D39: R | E39: 抽卡 | G39: P02 | H39: 0

Sheet GachaRule
A1: key | B1: value | C1: desc
A2: string | B2: string | C2: string
A3: Key | B3: 值 | C3: 说明
A4: ssr_rate | B4: 0.01 | C4: SSR 基础概率
A5: sr_rate | B5: 0.06 | C5: SR 基础概率
A6: r_rate | B6: 0.28 | C6: R 基础概率
A7: n_rate | B7: 0.65 | C7: N 基础概率
A8: soft_pity_start | B8: 40 | C8: SSR 软保底起点（第 N 抽起概率递增）
A9: soft_pity_step | B9: 0.04 | C9: SSR 软保底每抽增幅
A10: hard_pity | B10: 60 | C10: SSR 硬保底（第 N 抽必出）
A11: sr_pity | B11: 10 | C11: 每 N 抽至少 1 个 SR 及以上
A12: up_rate | B12: 0.5 | C12: 出 SSR 时为 UP 的概率
A13: up_guarantee | B13: 1 | C13: 是否启用大保底（未中 UP 则下个 SSR 必为 UP，1=是）
A14: cost_ticket | B14: 1 | C14: 单抽消耗抽卡券
A15: cost_gem | B15: 160 | C15: 单抽消耗钻石
... A20: log_keep | B20: 100 | C20: 抽卡记录保留条数
A21: pull_times_allowed | B21: 1;10 | C21: 允许的单次抽数

Sheet GachaPool
A1: poolId | B1: name | C1: type | D1: activityId | E1: upItemIds | F1: hasUp
A2: string | B2: string | C2: string | D2: string | E2: string | F2: int
A3: 卡池ID | B3: 名称 | C3: 类型 | D3: 关联活动 | E3: UP 物品ID | F3: 是否有UP(0/1)
A4: P01 | B4: 常驻池 | C4: 常驻 | F4: 0
A5: P02 | B5: 春日野餐 | C5: 限时 | D5: A001 | E5: 7101;7102 | F5: 1

Sheet GachaPoolItem
A1: poolId | B1: rarity | C1: itemId | D1: weight | E1: isUp | F1: #shareInGroup | G1: #itemName
A2: string | B2: string | C2: int | D2: int | E2: int | F2: calc | G2: calc
A3: 卡池ID | B3: 稀有度 | C3: 外观ID | D3: 池内权重 | E3: UP 组(0/1) | F3: 组内占比 | G3: 外观名称
A4: P01 | B4: SSR | C4: 7005 | D4: 1 | E4: 0 | F4: =D4/SUMIFS($D$4:$D$57,$A$4:$A$57,A4,$B$4:$B$57,B4,$E$4:$E$57,E4) -> 0.33333333 | G4: =INDEX(AvatarItem!$B$4:$B$39,MATCH(C4,AvatarItem!$A$4:$A$39,0)) -> 星光长发
A5: P01 | B5: SSR | C5: 7024 | D5: 1 | E5: 0 | F5: =D5/SUMIFS($D$4:$D$57,$A$4:$A$57,A5,$B$4:$B$57,B5,$E$4:$E$57,E5) -> 0.33333333 | G5: =INDEX(AvatarItem!$B$4:$B$39,MATCH(C5,AvatarItem!$A$4:$A$39,0)) -> 月光皇冠
A6: P01 | B6: SSR | C6: 7030 | D6: 1 | E6: 0 | F6: =D6/SUMIFS($D$4:$D$57,$A$4:$A$57,A6,$B$4:$B$57,B6,$E$4:$E$57,E6) -> 0.33333333 | G6: =INDEX(AvatarItem!$B$4:$B$39,MATCH(C6,AvatarItem!$A$4:$A$39,0)) -> 星河长裙
A7: P01 | B7: SR | C7: 7004 | D7: 1 | E7: 0 | F7: =D7/SUMIFS($D$4:$D$57,$A$4:$A$57,A7,$B$4:$B$57,B7,$E$4:$E$57,E7) -> 0.2 | G7: =INDEX(AvatarItem!$B$4:$B$39,MATCH(C7,AvatarItem!$A$4:$A$39,0)) -> 长发·樱粉
A8: P01 | B8: SR | C8: 7010 | D8: 1 | E8: 0 | F8: =D8/SUMIFS($D$4:$D$57,$A$4:$A$57,A8,$B$4:$B$57,B8,$E$4:$E$57,E8) -> 0.2 | G8: =INDEX(AvatarItem!$B$4:$B$39,MATCH(C8,AvatarItem!$A$4:$A$39,0)) -> 刺绣衬衫
A9: P01 | B9: SR | C9: 7015 | D9: 1 | E9: 0 | F9: =D9/SUMIFS($D$4:$D$57,$A$4:$A$57,A9,$B$4:$B$57,B9,$E$4:$E$57,E9) -> 0.2 | G9: =INDEX(AvatarItem!$B$4:$B$39,MATCH(C9,AvatarItem!$A$4:$A$39,0)) -> 灯笼裤
A10: P01 | B10: SR | C10: 7019 | D10: 1 | E10: 0 | F10: =D10/SUMIFS($D$4:$D$57,$A$4:$A$57,A10,$B$4:$B$57,B10,$E$4:$E$57,E10) -> 0.2 | G10: =INDEX(AvatarItem!$B$4:$B$39,MATCH(C10,AvatarItem!$A$4:$A$39,0)) -> 云朵运动鞋
A11: P01 | B11: SR | C11: 7029 | D11: 1 | E11: 0 | F11: =D11/SUMIFS($D$4:$D$57,$A$4:$A$57,A11,$B$4:$B$57,B11,$E$4:$E$57,E11) -> 0.2 | G11: =INDEX(AvatarItem!$B$4:$B$39,MATCH(C11,AvatarItem!$A$4:$A$39,0)) -> 云朵翅膀
A12: P01 | B12: R | C12: 7003 | D12: 1 | E12: 0 | F12: =D12/SUMIFS($D$4:$D$57,$A$4:$A$57,A12,$B$4:$B$57,B12,$E$4:$E$57,E12) -> 0.1 | G12: =INDEX(AvatarItem!$B$4:$B$39,MATCH(C12,AvatarItem!$A$4:$A$39,0)) -> 卷发·栗
A13: P01 | B13: R | C13: 7008 | D13: 1 | E13: 0 | F13: =D13/SUMIFS($D$4:$D$57,$A$4:$A$57,A13,$B$4:$B$57,B13,$E$4:$E$57,E13) -> 0.1 | G13: =INDEX(AvatarItem!$B$4:$B$39,MATCH(C13,AvatarItem!$A$4:$A$39,0)) -> 针织背心
A14: P01 | B14: R | C14: 7009 | D14: 1 | E14: 0 | F14: =D14/SUMIFS($D$4:$D$57,$A$4:$A$57,A14,$B$4:$B$57,B14,$E$4:$E$57,E14) -> 0.1 | G14: =INDEX(AvatarItem!$B$4:$B$39,MATCH(C14,AvatarItem!$A$4:$A$39,0)) -> 工装外套
A15: P01 | B15: R | C15: 7013 | D15: 1 | E15: 0 | F15: =D15/SUMIFS($D$4:$D$57,$A$4:$A$57,A15,$B$4:$B$57,B15,$E$4:$E$57,E15) -> 0.1 | G15: =INDEX(AvatarItem!$B$4:$B$39,MATCH(C15,AvatarItem!$A$4:$A$39,0)) -> 工装长裤
... A57: P02 | B57: N | C57: 7026 | D57: 1 | E57: 0 | F57: =D57/SUMIFS($D$4:$D$57,$A$4:$A$57,A57,$B$4:$B$57,B57,$E$4:$E$57,E57) -> 0.16666667 | G57: =INDEX(AvatarItem!$B$4:$B$39,MATCH(C57,AvatarItem!$A$4:$A$39,0)) -> 圆框眼镜

Sheet GachaSim
A1: SSR 保底概率模型（全部由公式计算，参数来自 GachaRule）
A2: 模型：基础概率 + 软保底（起点后每抽递增）+ 硬保底；不含 UP 逻辑。第 n 抽出 SSR 概率 p(n) 见下表。
A3: 参数 | B3: 值 | D3: 结果 | E3: 值
A4: 基础概率 | B4: =GachaRule!$B$4 -> 0.01 | D4: 平均出 SSR 所需抽数 | E4: =SUM(E20:E79) -> 36.3041
A5: 软保底起点 | B5: =GachaRule!$B$8 -> 40 | D5: N1 抽内出 SSR 概率 | E5: =INDEX(F20:F79,B9) -> 0.3580574
A6: 软保底每抽增幅 | B6: =GachaRule!$B$9 -> 0.04 | D6: N2 抽内出 SSR 概率 | E6: =INDEX(F20:F79,B10) -> 0.9756941
A7: 硬保底 | B7: =GachaRule!$B$10 -> 60 | D7: 综合 SSR 出率（含保底） | E7: =1/E4 -> 0.027545098
A8: UP 概率 | B8: =GachaRule!$B$12 -> 0.5 | D8: 平均出 UP 所需抽数（含大保底） | E8: =E4*(1+(1-B8)) -> 54.45615
A9: 查询抽数 N1（可改） | B9: 40 | D9: 概率分布求和（应为 100%） | E9: =SUM(D20:D79) -> 1
A10: 查询抽数 N2（可改） | B10: 50
A12: 说明：SR 综合出率等需要 SR 保底与 SSR 保底联动，用蒙特卡洛脚本模拟（200,000 次），结果见『校验』表的静态参考值。
A19: n（距上次 SSR 的第几抽） | B19: p(n) 本抽出 SSR 概率 | C19: 前 n−1 抽均未出 SSR 的概率 | D19: 恰好第 n 抽首次出 SSR | E19: n × 概率 | F19: 累计概率
A20: 1 | B20: =IF(A20>=$B$7,1,IF(A20>=$B$5,MIN(1,$B$4+$B$6*(A20-$B$5+1)),$B$4)) -> 0.01 | C20: =1 -> 1 | D20: =C20*B20 -> 0.01 | E20: =A20*D20 -> 0.01 | F20: =SUM($D$20:D20) -> 0.01
A21: 2 | B21: =IF(A21>=$B$7,1,IF(A21>=$B$5,MIN(1,$B$4+$B$6*(A21-$B$5+1)),$B$4)) -> 0.01 | C21: =C20*(1-B20) -> 0.99 | D21: =C21*B21 -> 0.0099 | E21: =A21*D21 -> 0.0198 | F21: =SUM($D$20:D21) -> 0.0199
A22: 3 | B22: =IF(A22>=$B$7,1,IF(A22>=$B$5,MIN(1,$B$4+$B$6*(A22-$B$5+1)),$B$4)) -> 0.01 | C22: =C21*(1-B21) -> 0.9801 | D22: =C22*B22 -> 0.009801 | E22: =A22*D22 -> 0.029403 | F22: =SUM($D$20:D22) -> 0.029701
A23: 4 | B23: =IF(A23>=$B$7,1,IF(A23>=$B$5,MIN(1,$B$4+$B$6*(A23-$B$5+1)),$B$4)) -> 0.01 | C23: =C22*(1-B22) -> 0.970299 | D23: =C23*B23 -> 0.00970299 | E23: =A23*D23 -> 0.03881196 | F23: =SUM($D$20:D23) -> 0.03940399
A24: 5 | B24: =IF(A24>=$B$7,1,IF(A24>=$B$5,MIN(1,$B$4+$B$6*(A24-$B$5+1)),$B$4)) -> 0.01 | C24: =C23*(1-B23) -> 0.96059601 | D24: =C24*B24 -> 0.0096059601 | E24: =A24*D24 -> 0.0480298 | F24: =SUM($D$20:D24) -> 0.04900995
A25: 6 | B25: =IF(A25>=$B$7,1,IF(A25>=$B$5,MIN(1,$B$4+$B$6*(A25-$B$5+1)),$B$4)) -> 0.01 | C25: =C24*(1-B24) -> 0.95099005 | D25: =C25*B25 -> 0.0095099005 | E25: =A25*D25 -> 0.057059403 | F25: =SUM($D$20:D25) -> 0.058519851
A26: 7 | B26: =IF(A26>=$B$7,1,IF(A26>=$B$5,MIN(1,$B$4+$B$6*(A26-$B$5+1)),$B$4)) -> 0.01 | C26: =C25*(1-B25) -> 0.94148015 | D26: =C26*B26 -> 0.0094148015 | E26: =A26*D26 -> 0.06590361 | F26: =SUM($D$20:D26) -> 0.067934652
A27: 8 | B27: =IF(A27>=$B$7,1,IF(A27>=$B$5,MIN(1,$B$4+$B$6*(A27-$B$5+1)),$B$4)) -> 0.01 | C27: =C26*(1-B26) -> 0.93206535 | D27: =C27*B27 -> 0.0093206535 | E27: =A27*D27 -> 0.074565228 | F27: =SUM($D$20:D27) -> 0.077255306
A28: 9 | B28: =IF(A28>=$B$7,1,IF(A28>=$B$5,MIN(1,$B$4+$B$6*(A28-$B$5+1)),$B$4)) -> 0.01 | C28: =C27*(1-B27) -> 0.92274469 | D28: =C28*B28 -> 0.0092274469 | E28: =A28*D28 -> 0.083047022 | F28: =SUM($D$20:D28) -> 0.086482753
A29: 10 | B29: =IF(A29>=$B$7,1,IF(A29>=$B$5,MIN(1,$B$4+$B$6*(A29-$B$5+1)),$B$4)) -> 0.01 | C29: =C28*(1-B28) -> 0.91351725 | D29: =C29*B29 -> 0.0091351725 | E29: =A29*D29 -> 0.091351725 | F29: =SUM($D$20:D29) -> 0.095617925
A30: 11 | B30: =IF(A30>=$B$7,1,IF(A30>=$B$5,MIN(1,$B$4+$B$6*(A30-$B$5+1)),$B$4)) -> 0.01 | C30: =C29*(1-B29) -> 0.90438208 | D30: =C30*B30 -> 0.0090438208 | E30: =A30*D30 -> 0.099482028 | F30: =SUM($D$20:D30) -> 0.10466175
A31: 12 | B31: =IF(A31>=$B$7,1,IF(A31>=$B$5,MIN(1,$B$4+$B$6*(A31-$B$5+1)),$B$4)) -> 0.01 | C31: =C30*(1-B30) -> 0.89533825 | D31: =C31*B31 -> 0.0089533825 | E31: =A31*D31 -> 0.10744059 | F31: =SUM($D$20:D31) -> 0.11361513
A32: 13 | B32: =IF(A32>=$B$7,1,IF(A32>=$B$5,MIN(1,$B$4+$B$6*(A32-$B$5+1)),$B$4)) -> 0.01 | C32: =C31*(1-B31) -> 0.88638487 | D32: =C32*B32 -> 0.0088638487 | E32: =A32*D32 -> 0.11523003 | F32: =SUM($D$20:D32) -> 0.12247898
... A79: 60 | B79: =IF(A79>=$B$7,1,IF(A79>=$B$5,MIN(1,$B$4+$B$6*(A79-$B$5+1)),$B$4)) -> 1 | C79: =C78*(1-B78) -> 1.2507996e-06 | D79: =C79*B79 -> 1.2507996e-06 | E79: =A79*D79 -> 7.5047974e-05 | F79: =SUM($D$20:D79) -> 1

Sheet Activity
A1: activityId | B1: name | C1: type | D1: poolId | E1: startTime | F1: endTime | G1: preloadSec | H1: resourceBundle | I1: entryIcon
A2: string | B2: string | C2: string | D2: string | E2: long | F2: long | G2: int | H2: string | I2: string
A3: 活动ID | B3: 名称 | C3: 类型 | D3: 卡池 | E3: 开始(UTC毫秒，由服务端配置) | F3: 结束(UTC毫秒，由服务端配置) | G3: 提前预下载(秒) | H3: 热更资源包名 | I3: 入口位置
A4: A001 | B4: 春日野餐 | C4: gacha | D4: P02 | G4: 259200 | H4: activity_spring_picnic | I4: 广场公告板;主界面
